Workbook
Name preferredAttributePTDMap: [1]AttributePTDMAP!$A$203:$B$204
Name attributeMapFeedProductType: [1]AttributePTDMAP!$B$1

Sheet 报关单
A1: 中华人民共和国海关出口货物报关单
A2: 预录入编号： | F2: 申报口岸: | I2: 海关编号:
A3: 境内发货人 | C3: 91410100MAKBTACC38 | E3: 出境关别 | F3: ( ) | G3: 出口日期 | K3: 申报日期 | O3: 备案号 | U3: 签约地点： | V3: XX
A4: 郑州嘉可文贸易有限公司 | K4: 46266 | U4: 成交方式: | V4: =I12 -> C&F | W4: ZHENGZHOU | X4: 付款条件： | Y4: 电汇
A5: 境外收货人 | C5: AEO： | D5: NO | E5: 运输方式 | F5: ( ) | G5: 运输工具名称及航次号 | K5: 提运单号 | U5: 卖方公司： | V5: =A4 -> 郑州嘉可文贸易有限公司
A6: Jiakewen Trading Limited | E6: 水路运输 | U6: 卖方地址： | V6: 河南省郑州市高新技术产业开发区冬青街26号3号楼2层9号237-1
A7: 生产销售单位 | C7: =C3 -> 91410100MAKBTACC38 | E7: 监管方式 | F7: ( ) | G7: 征免性质 | H7: ( ) | K7: 许可证号 | U7: 卖方电话： | V7: XXXX | X7: 卖方传真： | Y7: XXXXXX
A8: =A4 -> 郑州嘉可文贸易有限公司 | E8: 0110 | G8: 一般征税 | U8: 买方公司： | V8: =A6 -> Jiakewen Trading Limited
A9: 合同协议号 | E9: 贸易国(地区) | F9: ( ) | G9: 运抵国(地区) | H9: ( ) | K9: 指运港 | L9: ( ) | O9: 离境口岸 | P9: ( ) | U9: 买方地址： | V9: 香港尖沙咀科學館道 14 號新文華中心 B 座 7 樓 701 室 108B 單位
A10: 2608300077 | E10: 香港 | G10: 美国 | K10: 美国 | U10: 买方电话： | X10: 买方传真：
A11: 包装种类 | C11: ( ) | E11: 件数 | F11: 毛重（千克） | G11: 净重（千克） | I11: 成交方式 | J11: ( ) | K11: 运费 | N11: 保费 | Q11: 杂费 | U11: 报关简称： | X11: 报关全称：
A12: 纸箱 | E12: =V18 -> 0 | F12: =U18 -> 0 | G12: =T18 -> 0 | I12: C&F | K12: USD/0/3 | T12: 境外收货人： | W12: 境外收货人通常指签订并执行出口贸易合同中的买方或合同指定的收货人，名称一般填报英文名称，检验检疫要求填报其他外文名称的，在英文名称后填报，以半角括号分隔。
A13: 随附单证及编号 | T13: 境外收货人代码： | W13: 非互认国家（地区）AEO企业等其他情形，编码免于填报。对于AEO互认国家（地区）企业的，编码填报AEO编码，填报样式按照海关总署发布的相关公告要求填报（如新加坡AEO企业填报样式为：SG123456789012，韩国AEO企业填报样式为KR1234567，具体见相关公告要求）。
A14: 境外收货人完整显示： | D14: =A6 -> Jiakewen Trading Limited | T14: 检验检疫附加编号： | W14: 通过以下网站输入10位HS编号，再根据申报要素细分确定3位检疫附加编号
A15: 标记唛码及备注： | T15: 检疫局网址-编码查询： | W15: https://e-service.shciq.gov.cn/shesp/
A16: 备注： | T16: 查申报要素网址： | W16: http://www.hscode.net/IntegrateQueries/QueryYS/
L17: 报关联系电话： | T17: 合计： | W17: 贸易国：出口是指合同买方所在的国家（地区），需填写准确，以后可能会影响收汇。
A18: 特殊关系确认: | D18: 价格影响确认： | F18: 支付特许权使用费: | I18: 自报自缴: | K18: 出口不填 | L18: 原产国/目的国/货源地未注明的项默认与提供的项相同 | T18: =SUM(T20:T429) -> 0 | U18: =SUM(U20:U429) -> 0 | V18: =SUM(V20:V429) -> 0
A19: 项号 | B19: 商品编号 | D19: 商品名称及规格型号 | G19: 数量及单位 | I19: 单价/总价/币制 | K19: 原产国（地区） | M19: 最终目的国（地区） | P19: 境内货源地 | S19: 征免 | T19: 净重 | U19: 毛重 | V19: 件数
A20: 1 | K20: 中国 | M20: 美国 | P20: 河北邢台 | S20: 照章征税
A23: 2 | K23: 中国 | M23: 美国 | P23: 河北邢台 | S23: 照章征税
A26: 3 | K26: 中国 | M26: 美国 | P26: 河北邢台 | S26: 照章征税
A29: 4 | K29: 中国 | M29: 美国 | P29: 河北邢台 | S29: 照章征税
A32: 5 | K32: 中国 | M32: 美国 | P32: 河北邢台 | S32: 照章征税
A35: 6
A38: 7
A41: 8
A44: 9
A47: 10
A50: 11
A53: 12
A56: 13
A59: 14
A62: 15
A65: 16
A68: 17
... A167: 50
BY182: 表格制作单位：深圳市长来运报关有限公司QQ1152276688

Sheet 发票
A1: 發票 INVOICE
F2: 編 號 NO: | G2: =报关单!A10 -> 2608300077
A3: 商 號 Sold to Massrs: | C3: =报关单!A6 -> Jiakewen Trading Limited | F3: 日 期 DATE: | G3: =报关单!K4-1 -> 46265
F6: 成交方式： | G6: =报关单!V4 -> C&F | H6: =报关单!W4 -> ZHENGZHOU
A7: 標記號碼 Mark & No | C7: 貨物名稱 Description | D7: 數量 Quantity | F7: 單價 Unit price | G7: 總金額 Amount
A8: N/M | C8: =OFFSET(报关单!$D$1,ROW(报关单!D1)*3+16,0) -> 0 | D8: =OFFSET(报关单!$G$1,ROW(报关单!G1)*3+18,0) -> 0 | E8: =OFFSET(报关单!$H$1,ROW(报关单!H1)*3+18,0) -> 0 | F8: =IFERROR(H8/D8,0) -> 0 | G8: =OFFSET(报关单!$I$1,ROW(报关单!I1)*3+18,0) -> 0 | H8: =OFFSET(报关单!$I$1,ROW(报关单!I1)*3+17,0) -> 0
C9: =OFFSET(报关单!$D$1,ROW(报关单!D2)*3+16,0) -> 0 | D9: =OFFSET(报关单!$G$1,ROW(报关单!G2)*3+18,0) -> 0 | E9: =OFFSET(报关单!$H$1,ROW(报关单!H2)*3+18,0) -> 0 | F9: =IFERROR(H9/D9,0) -> 0 | G9: =OFFSET(报关单!$I$1,ROW(报关单!I2)*3+18,0) -> 0 | H9: =OFFSET(报关单!$I$1,ROW(报关单!I2)*3+17,0) -> 0
C10: =OFFSET(报关单!$D$1,ROW(报关单!D3)*3+16,0) -> 0 | D10: =OFFSET(报关单!$G$1,ROW(报关单!G3)*3+18,0) -> 0 | E10: =OFFSET(报关单!$H$1,ROW(报关单!H3)*3+18,0) -> 0 | F10: =IFERROR(H10/D10,0) -> 0 | G10: =OFFSET(报关单!$I$1,ROW(报关单!I3)*3+18,0) -> 0 | H10: =OFFSET(报关单!$I$1,ROW(报关单!I3)*3+17,0) -> 0
C11: =OFFSET(报关单!$D$1,ROW(报关单!D4)*3+16,0) -> 0 | D11: =OFFSET(报关单!$G$1,ROW(报关单!G4)*3+18,0) -> 0 | E11: =OFFSET(报关单!$H$1,ROW(报关单!H4)*3+18,0) -> 0 | F11: =IFERROR(H11/D11,0) -> 0 | G11: =OFFSET(报关单!$I$1,ROW(报关单!I4)*3+18,0) -> 0 | H11: =OFFSET(报关单!$I$1,ROW(报关单!I4)*3+17,0) -> 0
C12: =OFFSET(报关单!$D$1,ROW(报关单!D5)*3+16,0) -> 0 | D12: =OFFSET(报关单!$G$1,ROW(报关单!G5)*3+18,0) -> 0 | E12: =OFFSET(报关单!$H$1,ROW(报关单!H5)*3+18,0) -> 0 | F12: =IFERROR(H12/D12,0) -> 0 | G12: =OFFSET(报关单!$I$1,ROW(报关单!I5)*3+18,0) -> 0 | H12: =OFFSET(报关单!$I$1,ROW(报关单!I5)*3+17,0) -> 0
C13: =OFFSET(报关单!$D$1,ROW(报关单!D6)*3+16,0) -> 0 | D13: =OFFSET(报关单!$G$1,ROW(报关单!G6)*3+18,0) -> 0 | E13: =OFFSET(报关单!$H$1,ROW(报关单!H6)*3+18,0) -> 0 | F13: =IFERROR(H13/D13,0) -> 0 | G13: =OFFSET(报关单!$I$1,ROW(报关单!I6)*3+18,0) -> 0 | H13: =OFFSET(报关单!$I$1,ROW(报关单!I6)*3+17,0) -> 0
C14: =OFFSET(报关单!$D$1,ROW(报关单!D7)*3+16,0) -> 0 | D14: =OFFSET(报关单!$G$1,ROW(报关单!G7)*3+18,0) -> 0 | E14: =OFFSET(报关单!$H$1,ROW(报关单!H7)*3+18,0) -> 0 | F14: =IFERROR(H14/D14,0) -> 0 | G14: =OFFSET(报关单!$I$1,ROW(报关单!I7)*3+18,0) -> 0 | H14: =OFFSET(报关单!$I$1,ROW(报关单!I7)*3+17,0) -> 0
C15: =OFFSET(报关单!$D$1,ROW(报关单!D8)*3+16,0) -> 0 | D15: =OFFSET(报关单!$G$1,ROW(报关单!G8)*3+18,0) -> 0 | E15: =OFFSET(报关单!$H$1,ROW(报关单!H8)*3+18,0) -> 0 | F15: =IFERROR(H15/D15,0) -> 0 | G15: =OFFSET(报关单!$I$1,ROW(报关单!I8)*3+18,0) -> 0 | H15: =OFFSET(报关单!$I$1,ROW(报关单!I8)*3+17,0) -> 0
C16: =OFFSET(报关单!$D$1,ROW(报关单!D9)*3+16,0) -> 0 | D16: =OFFSET(报关单!$G$1,ROW(报关单!G9)*3+18,0) -> 0 | E16: =OFFSET(报关单!$H$1,ROW(报关单!H9)*3+18,0) -> 0 | F16: =IFERROR(H16/D16,0) -> 0 | G16: =OFFSET(报关单!$I$1,ROW(报关单!I9)*3+18,0) -> 0 | H16: =OFFSET(报关单!$I$1,ROW(报关单!I9)*3+17,0) -> 0
C17: =OFFSET(报关单!$D$1,ROW(报关单!D10)*3+16,0) -> 0 | D17: =OFFSET(报关单!$G$1,ROW(报关单!G10)*3+18,0) -> 0 | E17: =OFFSET(报关单!$H$1,ROW(报关单!H10)*3+18,0) -> 0 | F17: =IFERROR(H17/D17,0) -> 0 | G17: =OFFSET(报关单!$I$1,ROW(报关单!I10)*3+18,0) -> 0 | H17: =OFFSET(报关单!$I$1,ROW(报关单!I10)*3+17,0) -> 0
C18: =OFFSET(报关单!$D$1,ROW(报关单!D11)*3+16,0) -> 0 | D18: =OFFSET(报关单!$G$1,ROW(报关单!G11)*3+18,0) -> 0 | E18: =OFFSET(报关单!$H$1,ROW(报关单!H11)*3+18,0) -> 0 | F18: =IFERROR(H18/D18,0) -> 0 | G18: =OFFSET(报关单!$I$1,ROW(报关单!I11)*3+18,0) -> 0 | H18: =OFFSET(报关单!$I$1,ROW(报关单!I11)*3+17,0) -> 0
C19: =OFFSET(报关单!$D$1,ROW(报关单!D12)*3+16,0) -> 0 | D19: =OFFSET(报关单!$G$1,ROW(报关单!G12)*3+18,0) -> 0 | E19: =OFFSET(报关单!$H$1,ROW(报关单!H12)*3+18,0) -> 0 | F19: =IFERROR(H19/D19,0) -> 0 | G19: =OFFSET(报关单!$I$1,ROW(报关单!I12)*3+18,0) -> 0 | H19: =OFFSET(报关单!$I$1,ROW(报关单!I12)*3+17,0) -> 0
C20: =OFFSET(报关单!$D$1,ROW(报关单!D13)*3+16,0) -> 0 | D20: =OFFSET(报关单!$G$1,ROW(报关单!G13)*3+18,0) -> 0 | E20: =OFFSET(报关单!$H$1,ROW(报关单!H13)*3+18,0) -> 0 | F20: =IFERROR(H20/D20,0) -> 0 | G20: =OFFSET(报关单!$I$1,ROW(报关单!I13)*3+18,0) -> 0 | H20: =OFFSET(报关单!$I$1,ROW(报关单!I13)*3+17,0) -> 0
... C23: =OFFSET(报关单!$D$1,ROW(报关单!D16)*3+16,0) -> 0 | D23: =OFFSET(报关单!$G$1,ROW(报关单!G16)*3+18,0) -> 0 | E23: =OFFSET(报关单!$H$1,ROW(报关单!H16)*3+18,0) -> 0 | F23: =IFERROR(H23/D23,0) -> 0 | G23: =OFFSET(报关单!$I$1,ROW(报关单!I16)*3+18,0) -> 0 | H23: =OFFSET(报关单!$I$1,ROW(报关单!I16)*3+17,0) -> 0
A24: =IF(G24="CNY","总计人民币:",IF(G24="USD","总计美元: "," ")) | C24: =H24 -> 0 | F24: TOTAL: | G24: =G8 -> 0 | H24: =SUM(H8:H23) -> 0
A25: 唛头 Marks | F25: 备注：
C31: .

Sheet 箱单
B2: 装 箱 单 PACKING LIST
F3: 日期 Date： | G3: =报关单!K4-1 -> 46265
F4: 发票编号 Invoice No: | G4: =发票!G2 -> 2608300077
A5: 客户 To Messrs: | B5: =发票!C3 -> Jiakewen Trading Limited | F5: 合同号 Contract No: | G5: =发票!G2 -> 2608300077
A7: 船名 Shipped by： | C7: 由 深圳 至 | D7: =报关单!M20 -> 美国 | F7: 付款条件 Terms of Payment: | G7: =报关单!Y4 -> 电汇
A9: 箱号 Ctn.No. | B9: 货物名称及规格 Description | C9: 箱数： Pkg： | D9: 数量： Ge.Quantity | F9: 毛重(KG)： G.W.(KG): | G9: 净重(KG)： N.W.(KG):
A10: =发票!A8 -> N/M | B10: =发票!C8 -> 0 | C10: =OFFSET(报关单!$V$1,ROW(报关单!V1)*3+16,0) -> 0 | D10: =发票!D8 -> 0 | E10: =发票!E8 -> 0 | F10: =OFFSET(报关单!$U$1,ROW(报关单!U1)*3+16,0) -> 0 | G10: =OFFSET(报关单!$T$1,ROW(报关单!T1)*3+16,0) -> 0
B11: =发票!C9 -> 0 | C11: =OFFSET(报关单!$V$1,ROW(报关单!V2)*3+16,0) -> 0 | D11: =发票!D9 -> 0 | E11: =发票!E9 -> 0 | F11: =OFFSET(报关单!$U$1,ROW(报关单!U2)*3+16,0) -> 0 | G11: =OFFSET(报关单!$T$1,ROW(报关单!T2)*3+16,0) -> 0
B12: =发票!C10 -> 0 | C12: =OFFSET(报关单!$V$1,ROW(报关单!V3)*3+16,0) -> 0 | D12: =发票!D10 -> 0 | E12: =发票!E10 -> 0 | F12: =OFFSET(报关单!$U$1,ROW(报关单!U3)*3+16,0) -> 0 | G12: =OFFSET(报关单!$T$1,ROW(报关单!T3)*3+16,0) -> 0
B13: =发票!C11 -> 0 | C13: =OFFSET(报关单!$V$1,ROW(报关单!V4)*3+16,0) -> 0 | D13: =发票!D11 -> 0 | E13: =发票!E11 -> 0 | F13: =OFFSET(报关单!$U$1,ROW(报关单!U4)*3+16,0) -> 0 | G13: =OFFSET(报关单!$T$1,ROW(报关单!T4)*3+16,0) -> 0
B14: =发票!C12 -> 0 | C14: =OFFSET(报关单!$V$1,ROW(报关单!V5)*3+16,0) -> 0 | D14: =发票!D12 -> 0 | E14: =发票!E12 -> 0 | F14: =OFFSET(报关单!$U$1,ROW(报关单!U5)*3+16,0) -> 0 | G14: =OFFSET(报关单!$T$1,ROW(报关单!T5)*3+16,0) -> 0
B15: =发票!C13 -> 0 | C15: =OFFSET(报关单!$V$1,ROW(报关单!V6)*3+16,0) -> 0 | D15: =发票!D13 -> 0 | E15: =发票!E13 -> 0 | F15: =OFFSET(报关单!$U$1,ROW(报关单!U6)*3+16,0) -> 0 | G15: =OFFSET(报关单!$T$1,ROW(报关单!T6)*3+16,0) -> 0
B16: =发票!C14 -> 0 | C16: =OFFSET(报关单!$V$1,ROW(报关单!V7)*3+16,0) -> 0 | D16: =发票!D14 -> 0 | E16: =发票!E14 -> 0 | F16: =OFFSET(报关单!$U$1,ROW(报关单!U7)*3+16,0) -> 0 | G16: =OFFSET(报关单!$T$1,ROW(报关单!T7)*3+16,0) -> 0
B17: =发票!C15 -> 0 | C17: =OFFSET(报关单!$V$1,ROW(报关单!V8)*3+16,0) -> 0 | D17: =发票!D15 -> 0 | E17: =发票!E15 -> 0 | F17: =OFFSET(报关单!$U$1,ROW(报关单!U8)*3+16,0) -> 0 | G17: =OFFSET(报关单!$T$1,ROW(报关单!T8)*3+16,0) -> 0
B18: =发票!C16 -> 0 | C18: =OFFSET(报关单!$V$1,ROW(报关单!V9)*3+16,0) -> 0 | D18: =发票!D16 -> 0 | E18: =发票!E16 -> 0 | F18: =OFFSET(报关单!$U$1,ROW(报关单!U9)*3+16,0) -> 0 | G18: =OFFSET(报关单!$T$1,ROW(报关单!T9)*3+16,0) -> 0
B19: =发票!C17 -> 0 | C19: =OFFSET(报关单!$V$1,ROW(报关单!V10)*3+16,0) -> 0 | D19: =发票!D17 -> 0 | E19: =发票!E17 -> 0 | F19: =OFFSET(报关单!$U$1,ROW(报关单!U10)*3+16,0) -> 0 | G19: =OFFSET(报关单!$T$1,ROW(报关单!T10)*3+16,0) -> 0
B20: =发票!C18 -> 0 | C20: =OFFSET(报关单!$V$1,ROW(报关单!V11)*3+16,0) -> 0 | D20: =发票!D18 -> 0 | E20: =发票!E18 -> 0 | F20: =OFFSET(报关单!$U$1,ROW(报关单!U11)*3+16,0) -> 0 | G20: =OFFSET(报关单!$T$1,ROW(报关单!T11)*3+16,0) -> 0
B21: =发票!C19 -> 0 | C21: =OFFSET(报关单!$V$1,ROW(报关单!V12)*3+16,0) -> 0 | D21: =发票!D19 -> 0 | E21: =发票!E19 -> 0 | F21: =OFFSET(报关单!$U$1,ROW(报关单!U12)*3+16,0) -> 0 | G21: =OFFSET(报关单!$T$1,ROW(报关单!T12)*3+16,0) -> 0
B22: =发票!C20 -> 0 | C22: =OFFSET(报关单!$V$1,ROW(报关单!V13)*3+16,0) -> 0 | D22: =发票!D20 -> 0 | E22: =发票!E20 -> 0 | F22: =OFFSET(报关单!$U$1,ROW(报关单!T13)*3+16,0) -> 0 | G22: =OFFSET(报关单!$T$1,ROW(报关单!T13)*3+16,0) -> 0
B23: =发票!C21 -> 0 | C23: =OFFSET(报关单!$V$1,ROW(报关单!V14)*3+16,0) -> 0 | D23: =发票!D21 -> 0 | E23: =发票!E21 -> 0 | F23: =OFFSET(报关单!$U$1,ROW(报关单!T14)*3+16,0) -> 0 | G23: =OFFSET(报关单!$T$1,ROW(报关单!T14)*3+16,0) -> 0
B24: =发票!C22 -> 0 | C24: =OFFSET(报关单!$V$1,ROW(报关单!T15)*3+16,0) -> 0 | D24: =发票!D22 -> 0 | E24: =发票!E22 -> 0
B25: =发票!C23 -> 0 | C25: =OFFSET(报关单!$V$1,ROW(报关单!T16)*3+16,0) -> 0 | D25: =发票!D23 -> 0 | E25: =发票!E23 -> 0
A26: 合计 Total | C26: =SUM(C10:C25) -> 0 | F26: =SUM(F10:F25) -> 0 | G26: =SUM(G10:G25) -> 0
A27: 唛头 Marks

Sheet 合同
B1: 合 同 SALES CONTRACT
B2: 卖 方： | C2: =报关单!V5 -> 郑州嘉可文贸易有限公司
B3: Sellers:
B4: 地 址： | C4: =报关单!V6 -> 河南省郑州市高新技术产业开发区冬青街26号3号楼2层9号237-1
B5: Address: | F5: 合同号码
B6: 电 话： | D6: 传 真 | F6: Contract No: | G6: =报关单!A10 -> 2608300077
B7: TEL: | D7: FAX: | F7: 日 期
B8: 买 方： | C8: =报关单!V8 -> Jiakewen Trading Limited | F8: Date: | G8: =报关单!K4-25 -> 46241
B9: Buyers： | F9: 签约地点
B10: 地 址： | C10: =报关单!V9 -> 香港尖沙咀科學館道 14 號新文華中心 B 座 7 樓 701 室 108B 單位 | F10: Signed at: | G10: =报关单!V3 -> XX
B11: Address: | F11: 成交方式： Trade Term: | G11: =报关单!V4 -> C&F | H11: =报关单!W4 -> ZHENGZHOU
B12: 电 话 | C12: =报关单!V10 -> 0 | D12: 传 真 | E12: =报关单!Y10 -> 0
B13: TEL: | D13: FAX:
B14: 经买卖双方确认根据下列条款订立本合同
B15: This contract is made out by the Sellers and Buyers as per the following terms and conditions mutuilly confirmed:
B16: (1)货物名称 | D16: (2) 数 量 | E16: (3)单 位 | F16: (4)单价 | G16: (5) 金 额
B17: Name of commodity | D17: Quantity | E17: Unit | F17: Unit Price | G17: Amount
B18: =发票!C8 -> 0 | D18: =发票!D8 -> 0 | E18: =发票!E8 -> 0 | F18: =发票!F8 -> 0 | G18: =发票!G8 -> 0 | H18: =发票!H8 -> 0
B19: =发票!C9 -> 0 | D19: =发票!D9 -> 0 | E19: =发票!E9 -> 0 | F19: =发票!F9 -> 0 | G19: =发票!G9 -> 0 | H19: =发票!H9 -> 0
B20: =发票!C10 -> 0 | D20: =发票!D10 -> 0 | E20: =发票!E10 -> 0 | F20: =发票!F10 -> 0 | G20: =发票!G10 -> 0 | H20: =发票!H10 -> 0
B21: =发票!C11 -> 0 | D21: =发票!D11 -> 0 | E21: =发票!E11 -> 0 | F21: =发票!F11 -> 0 | G21: =发票!G11 -> 0 | H21: =发票!H11 -> 0
B22: =发票!C12 -> 0 | D22: =发票!D12 -> 0 | E22: =发票!E12 -> 0 | F22: =发票!F12 -> 0 | G22: =发票!G12 -> 0 | H22: =发票!H12 -> 0
B23: =发票!C13 -> 0 | D23: =发票!D13 -> 0 | E23: =发票!E13 -> 0 | F23: =发票!F13 -> 0 | G23: =发票!G13 -> 0 | H23: =发票!H13 -> 0
B24: =发票!C14 -> 0 | D24: =发票!D14 -> 0 | E24: =发票!E14 -> 0 | F24: =发票!F14 -> 0 | G24: =发票!G14 -> 0 | H24: =发票!H14 -> 0
B25: =发票!C15 -> 0 | D25: =发票!D15 -> 0 | E25: =发票!E15 -> 0 | F25: =发票!F15 -> 0 | G25: =发票!G15 -> 0 | H25: =发票!H15 -> 0
B26: =发票!C16 -> 0 | D26: =发票!D16 -> 0 | E26: =发票!E16 -> 0 | F26: =发票!F16 -> 0 | G26: =发票!G16 -> 0 | H26: =发票!H16 -> 0
B27: =发票!C17 -> 0 | D27: =发票!D17 -> 0 | E27: =发票!E17 -> 0 | F27: =发票!F17 -> 0 | G27: =发票!G17 -> 0 | H27: =发票!H17 -> 0
B28: =发票!C18 -> 0 | D28: =发票!D18 -> 0 | E28: =发票!E18 -> 0 | F28: =发票!F18 -> 0 | G28: =发票!G18 -> 0 | H28: =发票!H18 -> 0
B29: =发票!C19 -> 0 | D29: =发票!D19 -> 0 | E29: =发票!E19 -> 0 | F29: =发票!F19 -> 0 | G29: =发票!G19 -> 0 | H29: =发票!H19 -> 0
... B33: =发票!C23 -> 0 | D33: =发票!D23 -> 0 | E33: =发票!E23 -> 0 | F33: =发票!F23 -> 0 | G33: =发票!G23 -> 0 | H33: =发票!H23 -> 0
B36: 数量及总值允许有 2 %的增减。 | F36: 总 值 | G36: =G18 -> 0 | H36: =SUM(H18:I35) -> 0
B37: 2 % more or less both in amount and quantity allowed. | F37: Total Amount:
B38: (6)合同总值（大写） | D38: =IF(G36="CNY","总计人民币:",IF(G36="USD","总计美元: "," ")) | E38: =H36 -> 0
B40: (7)包装及唛头
B41: Packing and shipping Marks:
B42: (8)装运期
B43: Time of Shipment: | C43: =TODAY()+15 -> 46281 | E43: 之前
B44: (9)装运口岸和目的地 深圳--- | D44: =箱单!D7 -> 美国 | E44: 准许分批与转船。
B45: Loading Port & Destination:From Shenzhen-- To the United States of America with transhipment and partial ship ments allowed
B46: (10)保险：由买方按发票全部金额110%投保至 为止的 险。按中国海洋运输保险条款为理。
...

Sheet 申报要素
A1: (产品或者包装上有明显的logo，带R，TM标识的商标必须申报为品牌，有显示型号（model，type no.）的必须申报为型号)(申报的牌子型号要在产品或包装上有一模一样显示，海关查货的话会去比对拍照，对不上会升级整车查验和压车改单）
A2: (申报的牌子型号要在产品或包装上有一模一样显示，海关查货的话会去比对拍照，对不上会升级整车查验和压车改单）
A3: 检验检疫附加编号：通过以下网站输入10位HS编号，再根据申报要素细分确定3位检疫附加编号
C4: https://e-service.shciq.gov.cn/shesp/
A5: 申报要素查询网址： | C5: http://www.hscode.net/IntegrateQueries/QueryYS/
A8: 申报要素
A9: 序号 | B9: 品名 | C9: 海关HS编码 | D9: 品牌 | E9: 型号 | F9: 品牌类型 | G9: 出口享惠情况 | H9: 其他申报要素
A10: 1
A11: 2
A12: 3
A13: 4
A14: 5
A15: 6
A16: 7
A17: 8

Sheet 填制规范
A1: 项目 | B1: 2018年8月实行新的报关单的填制规范，红色为新增的项目
A3: 境内收发货人 | B3: 填报在海关备案的对外签订并执行进出口贸易合同的中国境内法人、其他组织名称及编码。编码填报18位法人和其他组织统一社会信用代码，没有统一社会信用代码的，填报其在海关的备案编码。
A5: 进出境关别 | B5: 根据货物实际进出境的口岸海关，填报海关规定的《关区代码表》中相应口岸海关的名称及代码。
A7: 备案号 | B7: 填报进出口货物收发货人、消费使用单位、生产销售单位在海关办理加工贸易合同备案或征、减、免税审核确认等手续时，海关核发的《加工贸易手册》、海关特殊监管区域和保税监管场所保税账册、《征免税证明》或其他备案审批文件的编号。一份报关单只允许填报一个备案号。
A9: 境外收发货人 | B9: 非互认国家（地区）AEO企业等其他情形，编码免于填报。境外收货人通常指签订并执行出口贸易合同中的买方或合同指定的收货人，境外发货人通常指签订并执行进口贸易合同中的卖方。填报境外收发货人的名称及编码。名称一般填报英文名称，检验检疫要求填报其他外文名称的，在英文名称后填报，以半角括号分隔；对于AEO互认国家（地区）企业的，编码填报AEO编码，填报样式按照海关总署发布的相关公告要求填报（如新加坡AEO企业填报样式为：SG123456789012，韩国AEO企业填报样式为KR1234567，具体见相关公告要求）。
A11: 货物存放地点-进口 | B11: 填报货物进境后存放的场所或地点，包括海关监管作业场所、分拨仓库、定点加工厂、隔离检疫场、企业自有仓库等。
A13: 消费使用单位-进口 | B13: 消费使用单位填报已知的进口货物在境内的最终消费、使用单位的名称，包括：1．自行进口货物的单位。2．委托进出口企业进口货物的单位。
A15: 生产销售单位-出口 | B15: 生产销售单位填报出口货物在境内的生产或销售单位的名称，包括：1．自行出口货物的单位。2．委托进出口企业出口货物的单位。
A17: 许可证号 | B17: 填报进（出）口许可证、两用物项和技术进（出）口许可证、两用物项和技术出口许可证（定向）、纺织品临时出口许可证、出口许可证（加工贸易）、出口许可证（边境小额贸易）的编号。一份报关单只允许填报一个许可证号。
A19: 启运港-进口 | B19: 填报进口货物在运抵我国关境前的第一个境外装运港。
A21: 合同协议号 | B21: 填报进出口货物合同（包括协议或订单）编号。未发生商业性交易的免予填报。
A23: 贸易国(地区) | B23: 发生商业性交易的进口填报购自国（地区），出口填报售予国（地区）。未发生商业性交易的填报货物所有权拥有者所属的国家（地区）。
... A91: 自报自缴 | B91: 进出口企业、单位采用“自主申报、自行缴税”（自报自缴）模式向海关申报时，填报“是”；反之则填报“否”。
